<?xml version="1.0"?>
<robot xmlns:xacro="http://www.ros.org/wiki/xacro" >

    
    <!-- <xacro:default_inertial mass="0.3"/> -->
    <!-- <xacro:default_inertial_1 mass="0.03"/> -->

    <xacro:macro name="default_transmission" params="number">
        <transmission name="transmission_${number}">
            <plugin>transmission_interface/SimpleTransmission</plugin>
            <actuator name="motor_${number}" role="actuator1"/>
            <joint name="joint_${number}"    role="joint1">
                <mechanical_reduction>1.0</mechanical_reduction>
            </joint>
        </transmission>
    </xacro:macro>

    
    <link name="world"/>

    <link name="base_link">
        <visual>
            <origin xyz="0.0 0.0 0.0" rpy="0.0 0.0 0.0"/>
            <geometry>
                <mesh filename="package://aster_description/meshes/ownStls/standBase.stl" scale="0.001 0.001 0.001"/>
            </geometry>        
            <material name="white"/>    
        </visual>
        <collision>
            <origin xyz="0.0 0.0 0.0" rpy="0.0 0.0 0.0"/>
            <geometry>
                <mesh filename="package://aster_description/meshes/ownStls/standBase.stl" scale="0.001 0.001 0.001"/>
            </geometry>  
        </collision>
        <xacro:default_inertial mass="3.3"/>
    </link>
    <!-- Base-->
    <link name="base_holder_link">
        <visual>
            <origin xyz="0.0 0.0 -0.02" rpy="0.0 0.0 ${-PI/2}"/>
            <geometry>
                <mesh filename="package://aster_description/meshes/subStuff/RohrHalter_v2.stl" scale="0.001 0.001 0.001"/>
            </geometry>         
            <material name="white"/>    
        </visual>
        <collision>
            <origin xyz="0.0 0.0 -0.02" rpy="0.0 0.0 ${-PI/2}"/>
            <geometry>
                <mesh filename="package://aster_description/meshes/subStuff/RohrHalter_v2.stl" scale="0.001 0.001 0.001"/>
            </geometry> 
        </collision>
        <xacro:default_inertial mass="0.3"/>
    </link>

    <link name="chest_bone_link">
        <visual>
            <origin xyz="0.0 0.0 0.0" rpy="0.0 0.0 0.0"/>
            <geometry>
                <mesh filename="package://aster_description/meshes/Spine_Connector.stl" scale="0.001 0.001 0.001"/>
            </geometry>      
            <material name="white"/>       
        </visual>
        <collision>
            <origin xyz="0.0 0.0 0.0" rpy="0.0 0.0 0.0"/>
            <geometry>
                <mesh filename="package://aster_description/meshes/Spine_Connector.stl" scale="0.001 0.001 0.001"/>
            </geometry>
        </collision>
        <xacro:default_inertial mass="0.3"/>
    </link>

    <link name="chest_link">
        <visual>
            <origin xyz="0.0 0.0 -0.012" rpy="0.0 0.0 0.0"/>
            <geometry>
                <mesh filename="package://aster_description/meshes/Chest.stl" scale="0.001 0.001 0.001"/>
            </geometry>      
            <material name="black"/>       
        </visual>
        <collision>
            <origin xyz="0.0 0.0 -0.012" rpy="0.0 0.0 0.0"/>
            <geometry>
                <mesh filename="package://aster_description/meshes/Chest.stl" scale="0.001 0.001 0.001"/>
            </geometry>  
        </collision>
        <xacro:default_inertial mass="0.3"/>
    </link>

    <link name="backbone_link">
        <visual>
            <origin xyz="-0.003 0.0 -0.085" rpy="0.0 0.0 0.0"/>
            <geometry>
                <mesh filename="package://aster_description/meshes/Spine.stl" scale="0.001 0.001 0.001"/>
            </geometry>      
            <material name="white"/>       
        </visual>
        <collision>
            <origin xyz="-0.003 0.0 -0.085" rpy="0.0 0.0 0.0"/>
            <geometry>
                <mesh filename="package://aster_description/meshes/Spine.stl" scale="0.001 0.001 0.001"/>
            </geometry>
        </collision>
        <xacro:default_inertial mass="0.3"/>
    </link>
 
    <link name="hip_link">
        <visual>
            <origin xyz="-0.005 0.0 0.003" rpy="0.0 0.0 0.0"/>
            <geometry>
                <mesh filename="package://aster_description/meshes/Hips.stl" scale="0.001 0.001 0.001"/>
            </geometry>      
            <material name="white"/>       
        </visual>
        <collision>
            <origin xyz="-0.005 0.0 0.003" rpy="0.0 0.0 0.0"/>
            <geometry>
                <mesh filename="package://aster_description/meshes/Hips.stl" scale="0.001 0.001 0.001"/>
            </geometry> 
        </collision>
        <xacro:default_inertial mass="0.3"/>
    </link>


   <!-- Head-->
    <link name="neck_link">
        <visual>
            <origin xyz="0.0 0.0 -0.012" rpy="0.0 0.0 0.0"/>
            <geometry>
                <mesh filename="package://aster_description/meshes/Head_Neck.stl" scale="0.001 0.001 0.001"/>
            </geometry>      
            <material name="blue"/>       
        </visual>
        <collision>
            <origin xyz="0.0 0.0 -0.012" rpy="0.0 0.0 0.0"/>
            <geometry>
                <mesh filename="package://aster_description/meshes/Head_Neck.stl" scale="0.001 0.001 0.001"/>
            </geometry> 
        </collision>
        <xacro:default_inertial mass="0.3"/>
    </link>

    <link name="head_link">
        <visual>
            <origin xyz="0.0 0.0 -0.012" rpy="0.0 0.0 0.0"/>
            <geometry>
                <mesh filename="package://aster_description/meshes/Head_Back.stl" scale="0.001 0.001 0.001"/>
            </geometry>      
            <material name="white"/>       
        </visual>
        <collision>
            <origin xyz="0.0 0.0 -0.012" rpy="0.0 0.0 0.0"/>
            <geometry>
                <mesh filename="package://aster_description/meshes/Head_Back.stl" scale="0.001 0.001 0.001"/>
            </geometry>
        </collision>
        <xacro:default_inertial mass="0.3"/>
    </link>

    <link name="face_link">
        <visual>
            <origin xyz="0.038 0 -0.0125" rpy="1.57 0 1.57"/>
            <geometry>
                <mesh filename="package://aster_description/meshes/ownStls/Face_OLED_PiCam.stl" scale="0.001 0.001 0.001"/>
            </geometry>      
            <material name="black"/>       
        </visual>
        <collision>
            <origin xyz="0.038 0 -0.0125" rpy="1.57 0 1.57"/>
            <geometry>
                <mesh filename="package://aster_description/meshes/ownStls/Face_OLED_PiCam.stl" scale="0.001 0.001 0.001"/>
            </geometry> 
        </collision>
        <xacro:default_inertial mass="0.3"/>
    </link>


    <!-- Right Arm-->
    <link name="shoulder_rh_link">
        <visual>
            <origin xyz="-0.01 -0.018 -0.023" rpy="0.0 0.0 0.0"/>
            <geometry>
                <mesh filename="package://aster_description/meshes/Rigth_Arm_Shoulder_Connector.stl" scale="0.001 0.001 0.001"/>
            </geometry>      
            <material name="white"/>       
        </visual>
        <collision>
            <origin xyz="-0.01 -0.018 -0.023" rpy="0.0 0.0 0.0"/>
            <geometry>
                <mesh filename="package://aster_description/meshes/Rigth_Arm_Shoulder_Connector.stl" scale="0.001 0.001 0.001"/>
            </geometry> 
        </collision>
        <xacro:default_inertial mass="0.3"/>
    </link>

    <link name="sh_rh_lift_link">
        <visual>
            <origin xyz="0 0.108 -0.6625" rpy="0.0 0.0 0.0"/>
            <geometry>
                <mesh filename="package://aster_description/meshes/Right_Arm_Shoulder.stl" scale="0.001 0.001 0.001"/>
            </geometry>      
            <material name="white"/>       
        </visual>
        <collision>
            <origin xyz="0 0.108 -0.6625" rpy="0.0 0.0 0.0"/>
            <geometry>
                <mesh filename="package://aster_description/meshes/Right_Arm_Shoulder.stl" scale="0.001 0.001 0.001"/>
            </geometry> 
        </collision>
        <xacro:default_inertial mass="0.3"/>
    </link>

    <link name="sh_rh_rotate_link">
        <visual>
            <origin xyz="0 0.108 0.51" rpy="${PI} 0 ${PI}"/>
            <geometry>
                <mesh filename="package://aster_description/meshes/Right_Arm_Upper.stl" scale="0.001 0.001 0.001"/>
            </geometry>      
            <material name="white"/>       
        </visual>
        <collision>
            <origin xyz="0 0.108 0.51" rpy="${PI} 0 ${PI}"/>
            <geometry>
                <mesh filename="package://aster_description/meshes/Right_Arm_Upper.stl" scale="0.001 0.001 0.001"/>
            </geometry> 
        </collision>
        <xacro:default_inertial mass="0.3"/>
    </link>

    <link name="elbow_rh_link">
        <visual>
            <origin xyz="-0.01 0.1075 -0.498" rpy="0 0 0"/>
            <geometry>
                <mesh filename="package://aster_description/meshes/Right_Arm_Lower.stl" scale="0.001 0.001 0.001"/>
            </geometry>      
            <material name="white"/>       
        </visual>
        <collision>
            <origin xyz="-0.01 0.1075 -0.498" rpy="0 0 0"/>
            <geometry>
                <mesh filename="package://aster_description/meshes/Right_Arm_Lower.stl" scale="0.001 0.001 0.001"/>
            </geometry> 
        </collision>
        <xacro:default_inertial mass="0.3"/>
    </link>

    <link name="rh_rotate_link" >
        <visual>
            <origin xyz="-0.02 0 -0.03" rpy="${-PI/2} 0 ${-PI/2}"/>
            <geometry>
                <mesh filename="package://aster_description/meshes/Greifer/files/Robotic_Arm_Palm.stl" scale="0.001 0.001 0.001"/>
            </geometry>      
            <material name="white"/>       
        </visual>
        <collision>
            <origin xyz="-0.02 0 -0.03" rpy="${-PI/2} 0 ${-PI/2}"/>
            <geometry>
                <mesh filename="package://aster_description/meshes/Greifer/files/Robotic_Arm_Palm.stl" scale="0.001 0.001 0.001"/>
            </geometry> 
        </collision>
        <xacro:default_inertial mass="0.3"/>
    </link>
   
    <!-- Right Gripper-->
    
    <link name="rh_rotate_top_link" >
        <visual>
            <origin xyz="-0.004 0 -0.03" rpy="${-PI/2} 0 ${-PI/2}"/>
            <geometry>
                <mesh filename="package://aster_description/meshes/Greifer/files/Robotic_Arm_Palm_Top.stl" scale="0.001 0.001 0.001"/>
            </geometry>      
            <material name="white"/>       
        </visual>
        <collision>
            <origin xyz="-0.004 0 -0.03" rpy="${-PI/2} 0 ${-PI/2}"/>
            <geometry>
                <mesh filename="package://aster_description/meshes/Greifer/files/Robotic_Arm_Palm_Top.stl" scale="0.001 0.001 0.001"/>
            </geometry>
        </collision>
        <xacro:default_inertial mass="0.3"/>
    </link>

    <link name="rh_gripper1_link" >
        <visual>
            <origin xyz="-0.005 0.016 -0.008" rpy="${-PI/2} 0 ${-PI/2}"/>
            <geometry>
                <mesh filename="package://aster_description/meshes/Greifer/files/Robotic_Arm_Finger.stl" scale="0.001 0.001 0.001"/>
            </geometry>      
            <material name="white"/>       
        </visual>
        <collision>
            <origin xyz="-0.005 0.016 -0.008" rpy="${-PI/2} 0 ${-PI/2}"/>
            <geometry>
                <mesh filename="package://aster_description/meshes/Greifer/files/Robotic_Arm_Finger.stl" scale="0.001 0.001 0.001"/>
            </geometry>
        </collision>
        <xacro:default_inertial mass="0.3"/>
    </link>

    <link name="rh_gripper2_link" >
        <visual>
            <origin xyz="0.007 -0.016 -0.008" rpy="${-PI/2} 0 ${PI/2}"/>
            <geometry>
                <mesh filename="package://aster_description/meshes/Greifer/files/Robotic_Arm_Finger.stl" scale="0.001 0.001 0.001"/>
            </geometry>      
            <material name="white"/>       
        </visual>
        <collision>
            <origin xyz="0.007 -0.016 -0.008" rpy="${-PI/2} 0 ${PI/2}"/>
            <geometry>
                <mesh filename="package://aster_description/meshes/Greifer/files/Robotic_Arm_Finger.stl" scale="0.001 0.001 0.001"/>
            </geometry>
        </collision>
        <xacro:default_inertial mass="0.3"/>
    </link>

    <link name="rh_gripper1_pad_link" >
        <visual>
            <origin xyz="-0.004 -0.0015 -0.0017" rpy="0 ${PI/2} 0"/>
            <geometry>
                <mesh filename="package://aster_description/meshes/Greifer/files/Robotic_Arm_Finger_Pad.stl" scale="0.001 0.001 0.001"/>
            </geometry>      
            <material name="black"/>       
        </visual>
        <collision>
            <origin xyz="-0.004 -0.0015 -0.0017" rpy="0 ${PI/2} 0"/>
            <geometry>
                <mesh filename="package://aster_description/meshes/Greifer/files/Robotic_Arm_Finger_Pad.stl" scale="0.001 0.001 0.001"/>
            </geometry>
        </collision>
        <xacro:default_inertial_1 mass="0.03"/>
    </link>

    <link name="rh_gripper2_pad_link" >
        <visual>
            <origin xyz="0.005 0.0015 -0.0017" rpy="${PI} ${PI/2} 0"/>
            <geometry>
                <mesh filename="package://aster_description/meshes/Greifer/files/Robotic_Arm_Finger_Pad.stl" scale="0.001 0.001 0.001"/>
            </geometry>      
            <material name="black"/>       
        </visual>
        <collision>
            <origin xyz="0.005 0.0015 -0.0017" rpy="${PI} ${PI/2} 0"/>
            <geometry>
                <mesh filename="package://aster_description/meshes/Greifer/files/Robotic_Arm_Finger_Pad.stl" scale="0.001 0.001 0.001"/>
            </geometry>
        </collision>
        <xacro:default_inertial_1 mass="0.03"/>
    </link>


    <!-- Left Arm-->
    <link name="shoulder_lh_link">
        <visual>
            <origin xyz="-0.01 0.018 -0.023" rpy="0.0 0.0 0.0"/>
            <geometry>
                <mesh filename="package://aster_description/meshes/Left_Arm_Shoulder_Connector.stl" scale="0.001 0.001 0.001"/>
            </geometry>      
            <material name="white"/>       
        </visual>
        <collision>
            <origin xyz="-0.01 0.018 -0.023" rpy="0.0 0.0 0.0"/>
            <geometry>
                <mesh filename="package://aster_description/meshes/Left_Arm_Shoulder_Connector.stl" scale="0.001 0.001 0.001"/>
            </geometry> 
        </collision>
        <xacro:default_inertial mass="0.3"/>
    </link>

    <link name="sh_lh_lift_link">
        <visual>
            <origin xyz="0 0 -0.036" rpy="0.0 0.0 0.0"/>
            <geometry>
                <mesh filename="package://aster_description/meshes/Left_Arm_Shoulder.stl" scale="0.001 0.001 0.001"/>
            </geometry>      
            <material name="white"/>       
        </visual>
        <collision>
            <origin xyz="0 0 -0.036" rpy="0.0 0.0 0.0"/>
            <geometry>
                <mesh filename="package://aster_description/meshes/Left_Arm_Shoulder.stl" scale="0.001 0.001 0.001"/>
            </geometry> 
        </collision>
        <xacro:default_inertial mass="0.3"/>
    </link>

    <link name="sh_lh_rotate_link">
        <visual>
            <origin xyz="0 0 -0.005" rpy="${PI} 0 ${PI}"/>
            <geometry>
                <mesh filename="package://aster_description/meshes/Left_Arm_Upper.stl" scale="0.001 0.001 0.001"/>
            </geometry>      
            <material name="white"/>       
        </visual>
        <collision>
            <origin xyz="0 0 -0.005" rpy="${PI} 0 ${PI}"/>
            <geometry>
                <mesh filename="package://aster_description/meshes/Left_Arm_Upper.stl" scale="0.001 0.001 0.001"/>
            </geometry>
        </collision>
        <xacro:default_inertial mass="0.3"/>
    </link>

    <link name="elbow_lh_link">
        <visual>
            <origin xyz="-0.06 0.002 -0.008" rpy="0 0 0"/>
            <geometry>
                <mesh filename="package://aster_description/meshes/Left_Arm_Lower.stl" scale="0.001 0.001 0.001"/>
            </geometry>      
            <material name="white"/>       
        </visual>
        <collision>
            <origin xyz="-0.06 0.002 -0.008" rpy="0 0 0"/>
            <geometry>
                <mesh filename="package://aster_description/meshes/Left_Arm_Lower.stl" scale="0.001 0.001 0.001"/>
            </geometry> 
        </collision>
        <xacro:default_inertial mass="0.3"/>
    </link>

    <link name="lh_rotate_link" >
        <visual>
            <origin xyz="-0.02 0 -0.03" rpy="${-PI/2} 0 ${-PI/2}"/>
            <geometry>
                <mesh filename="package://aster_description/meshes/Greifer/files/Robotic_Arm_Palm.stl" scale="0.001 0.001 0.001"/>
            </geometry>      
            <material name="white"/>       
        </visual>
        <collision>
            <origin xyz="-0.02 0 -0.03" rpy="${-PI/2} 0 ${-PI/2}"/>
            <geometry>
                <mesh filename="package://aster_description/meshes/Greifer/files/Robotic_Arm_Palm.stl" scale="0.001 0.001 0.001"/>
            </geometry>
        </collision>
        <xacro:default_inertial mass="0.3"/>
    </link>

    <!-- Left Gripper-->

    
    <link name="lh_rotate_top_link" >
        <visual>
            <origin xyz="-0.004 0 -0.03" rpy="${-PI/2} 0 ${-PI/2}"/>
            <geometry>
                <mesh filename="package://aster_description/meshes/Greifer/files/Robotic_Arm_Palm_Top.stl" scale="0.001 0.001 0.001"/>
            </geometry>      
            <material name="white"/>       
        </visual>
        <collision>
            <origin xyz="-0.004 0 -0.03" rpy="${-PI/2} 0 ${-PI/2}"/>
            <geometry>
                <mesh filename="package://aster_description/meshes/Greifer/files/Robotic_Arm_Palm_Top.stl" scale="0.001 0.001 0.001"/>
            </geometry> 
        </collision>
        <xacro:default_inertial mass="0.3"/>
    </link>

    <link name="lh_gripper1_link" >
        <visual>
            <origin xyz="-0.005 0.016 -0.008" rpy="${-PI/2} 0 ${-PI/2}"/>
            <geometry>
                <mesh filename="package://aster_description/meshes/Greifer/files/Robotic_Arm_Finger.stl" scale="0.001 0.001 0.001"/>
            </geometry>      
            <material name="white"/>       
        </visual>
        <collision>
            <origin xyz="-0.005 0.016 -0.008" rpy="${-PI/2} 0 ${-PI/2}"/>
            <geometry>
                <mesh filename="package://aster_description/meshes/Greifer/files/Robotic_Arm_Finger.stl" scale="0.001 0.001 0.001"/>
            </geometry>
        </collision>
        <xacro:default_inertial mass="0.3"/>
    </link>

    <link name="lh_gripper2_link" >
        <visual>
            <origin xyz="0.007 -0.016 -0.008" rpy="${-PI/2} 0 ${PI/2}"/>
            <geometry>
                <mesh filename="package://aster_description/meshes/Greifer/files/Robotic_Arm_Finger.stl" scale="0.001 0.001 0.001"/>
            </geometry>      
            <material name="white"/>       
        </visual>
        <collision>
            <origin xyz="0.007 -0.016 -0.008" rpy="${-PI/2} 0 ${PI/2}"/>
            <geometry>
                <mesh filename="package://aster_description/meshes/Greifer/files/Robotic_Arm_Finger.stl" scale="0.001 0.001 0.001"/>
            </geometry>
        </collision>
        <xacro:default_inertial mass="0.3"/>
    </link>

    <link name="lh_gripper1_pad_link" >
        <visual>
            <origin xyz="-0.004 -0.0015 -0.0017" rpy="0 ${PI/2} 0"/>
            <geometry>
                <mesh filename="package://aster_description/meshes/Greifer/files/Robotic_Arm_Finger_Pad.stl" scale="0.001 0.001 0.001"/>
            </geometry>      
            <material name="black"/>       
        </visual>
        <collision>
            <origin xyz="-0.004 -0.0015 -0.0017" rpy="0 ${PI/2} 0"/>
            <geometry>
                <mesh filename="package://aster_description/meshes/Greifer/files/Robotic_Arm_Finger_Pad.stl" scale="0.001 0.001 0.001"/>
            </geometry>
        </collision>
        <xacro:default_inertial mass="0.3"/>
    </link>

    <link name="lh_gripper2_pad_link" >
        <visual>
            <origin xyz="0.005 0.0015 -0.0017" rpy="${PI} ${PI/2} 0"/>
            <geometry>
                <mesh filename="package://aster_description/meshes/Greifer/files/Robotic_Arm_Finger_Pad.stl" scale="0.001 0.001 0.001"/>
            </geometry>      
            <material name="black"/>       
        </visual>
        <collision>
            <origin xyz="0.005 0.0015 -0.0017" rpy="${PI} ${PI/2} 0"/>
            <geometry>
                <mesh filename="package://aster_description/meshes/Greifer/files/Robotic_Arm_Finger_Pad.stl" scale="0.001 0.001 0.001"/>
            </geometry>
        </collision>
        <xacro:default_inertial mass="0.3"/>
    </link>

    <!-- Right Leg-->

    <link name="hip_rh_link">
        <visual>
            <origin xyz="0.0023 -0.015 -0.1748" rpy="0 0 0"/>
            <geometry>
                <mesh filename="package://aster_description/meshes/Right_Leg_Upper.stl" scale="0.001 0.001 0.001"/>
            </geometry>      
            <material name="white"/>       
        </visual>
        <collision>
            <origin xyz="0.0023 -0.015 -0.1748" rpy="0 0 0"/>
            <geometry>
                <mesh filename="package://aster_description/meshes/Right_Leg_Upper.stl" scale="0.001 0.001 0.001"/>
            </geometry> 
        </collision>
        <xacro:default_inertial mass="0.3"/>
    </link>

    <link name="knie_rh_link" >
        <visual>
            <origin xyz="0.0025 0 -0.1765" rpy="0 0 0"/>
            <geometry>
                <mesh filename="package://aster_description/meshes/Right_Leg_Lower.stl" scale="0.001 0.001 0.001"/>
            </geometry>      
            <material name="white"/>       
        </visual>
        <collision>
            <origin xyz="0.0025 0 -0.1765" rpy="0 0 0"/>
            <geometry>
                <mesh filename="package://aster_description/meshes/Right_Leg_Lower.stl" scale="0.001 0.001 0.001"/>
            </geometry>
        </collision>
        <xacro:default_inertial mass="0.3"/>
    </link>

    <link name="foot_rh_link" >
        <visual>
            <origin xyz="0.03 -0.0025 -0.035" rpy="0 0 0"/>
            <geometry>
                <mesh filename="package://aster_description/meshes/Right_Leg_Foot.stl" scale="0.001 0.001 0.001"/>
            </geometry>      
            <material name="black"/>       
        </visual>
        <collision>
            <origin xyz="0.03 -0.0025 -0.035" rpy="0 0 0"/>
            <geometry>
                <mesh filename="package://aster_description/meshes/Right_Leg_Foot.stl" scale="0.001 0.001 0.001"/>
            </geometry>
        </collision>
        <xacro:default_inertial mass="0.3"/>
    </link>

    <!-- Left Leg-->

    <link name="hip_lh_link">
        <visual>
            <origin xyz="0.0023 0.015 -0.1748" rpy="0 0 0"/>
            <geometry>
                <mesh filename="package://aster_description/meshes/Left_Leg_Upper.stl" scale="0.001 0.001 0.001"/>
            </geometry>      
            <material name="white"/>       
        </visual>
        <collision>
            <origin xyz="0.0023 0.015 -0.1748" rpy="0 0 0"/>
            <geometry>
                <mesh filename="package://aster_description/meshes/Left_Leg_Upper.stl" scale="0.001 0.001 0.001"/>
            </geometry>
        </collision>
        <xacro:default_inertial mass="0.3"/>
    </link>

    <link name="knie_lh_link" >
        <visual>
            <origin xyz="0.0025 0 -0.1765" rpy="0 0 0"/>
            <geometry>
                <mesh filename="package://aster_description/meshes/Left_Lower_Leg.stl" scale="0.001 0.001 0.001"/>
            </geometry>      
            <material name="black"/>       
        </visual>
        <collision>
            <origin xyz="0.0025 0 -0.1765" rpy="0 0 0"/>
            <geometry>
                <mesh filename="package://aster_description/meshes/Left_Lower_Leg.stl" scale="0.001 0.001 0.001"/>
            </geometry> 
        </collision>
        <xacro:default_inertial mass="0.3"/>
    </link>

    <link name="foot_lh_link" >
        <visual>
            <origin xyz="0.03 0.0025 -0.035" rpy="0 0 0"/>
            <geometry>
                <mesh filename="package://aster_description/meshes/Left_Leg_Foot.stl" scale="0.001 0.001 0.001"/>
            </geometry>      
            <material name="black"/>       
        </visual>
        <collision>
            <origin xyz="0.03 0.0025 -0.035" rpy="0 0 0"/>
            <geometry>
                <mesh filename="package://aster_description/meshes/Left_Leg_Foot.stl" scale="0.001 0.001 0.001"/>
            </geometry> 
        </collision>
        <xacro:default_inertial mass="0.3"/>
    </link>


                    <!-- ######  JOINTS  ######-->


    <!-- Base Virtual Joints-->
    <joint name="world_to_base" type="fixed">
        <parent link="world"/>
        <child link="base_link"/>
        <origin xyz="0.0 0.0 0.0" rpy="0.0 0.0 0.0"/>
    </joint>

    <joint name="base_to_holder" type="fixed">
        <parent link="base_link"/>
        <child link="base_holder_link"/>
        <origin xyz="0.0 0.0 0.62" rpy="0.0 0.0 0.0"/>
    </joint>

    <joint name="baseholder_to_chestbone" type="fixed">
        <parent link="base_holder_link"/>
        <child link="chest_bone_link"/>
        <origin xyz="0.042 0.0 0.015" rpy="0.0 0.0 0.0"/>
    </joint>

    <joint name="chestbone_to_chest" type="fixed">
        <parent link="chest_bone_link"/>
        <child link="chest_link"/>
        <origin xyz="0 0 0" rpy="0.0 0.0 0.0"/>
    </joint>

    <joint name="chestbone_to_backbone" type="fixed">
        <parent link="chest_bone_link"/>
        <child link="backbone_link"/>
        <origin xyz="0 0 0" rpy="0.0 0.0 0.0"/>
    </joint>

    <joint name="backbone_to_hip" type="fixed">
        <parent link="backbone_link"/>
        <child link="hip_link"/>
        <origin xyz="0 0 -0.2" rpy="0.0 0.0 0.0"/>
    </joint>


     <!--Head Joints-->
    <joint name="joint_1" type="revolute">
        <parent link="chest_link"/>
        <child link="neck_link"/>
        <axis xyz="0 0 1 "/>
        <limit lower="${-PI/2}" upper="${PI/2}" velocity="50.0" effort="1000.0"/>
        <origin xyz="0 0 0.1" rpy="0 0 0"/>
    </joint>

    <joint name="joint_2" type="revolute">
        <parent link="neck_link"/>
        <child link="head_link"/>
        <axis xyz="0 1 0"/>
        <limit lower="-0.5" upper="0.3" velocity="50.0" effort="1000.0"/>
        <origin xyz="0 0 0.01" rpy="0 0 0"/>
    </joint>

    <joint name="face_joint" type="fixed">
        <parent link="head_link"/>
        <child link="face_link"/>
        <origin xyz="0.0 0.0 0.0375" rpy="0.0 0.0 0.0"/>
    </joint>
    

    <!-- Right Arm Joints-->
    <joint name="joint_3" type="revolute">
        <parent link="chest_link"/>
        <child link="shoulder_rh_link"/>
        <axis xyz="0 1 0"/>
        <limit lower="${-PI/2}" upper="${PI/2}" velocity="50.0" effort="1000.0"/>
        <origin xyz="0.0 -0.085 0.05" rpy="0 0 0"/>
    </joint>

    <joint name="joint_4" type="revolute">
        <parent link="shoulder_rh_link"/>
        <child link="sh_rh_lift_link"/>
        <axis xyz="1 0 0"/>
        <limit lower="${-PI/2}" upper="0" velocity="50.0" effort="1000.0"/>
        <origin xyz="-0.008 -0.027 0" rpy="0 0 0"/>
    </joint>

    <joint name="joint_5" type="revolute">
        <parent link="sh_rh_lift_link"/>
        <child link="sh_rh_rotate_link"/>
        <axis xyz="0 0 1"/>
        <limit lower="${-PI/2}" upper="${PI/2}" velocity="50.0" effort="1000.0"/>
        <origin xyz="0 0 -0.04" rpy="0 0 0"/>
    </joint>
    
    <joint name="joint_6" type="revolute">
        <parent link="sh_rh_rotate_link"/>
        <child link="elbow_rh_link"/>
        <axis xyz="0 1 0"/>
        <limit lower="${-PI/2}" upper="0" velocity="50.0" effort="1000.0"/>
        <origin xyz="0 0 -0.13" rpy="0 0 0"/>
    </joint>

    <joint name="joint_7" type="revolute">
        <parent link="elbow_rh_link"/>
        <child link="rh_rotate_link"/>
        <axis xyz="0 0 1"/>
        <limit lower="0" upper="${PI/2}" velocity="50.0" effort="1000.0"/>
        <origin xyz="0 -0.01 -0.13" rpy="0 0 0"/>
    </joint>

    <!-- Right Gripper Joints-->
    
    <joint name="gripper_body_rh" type="fixed">
        <parent link="rh_rotate_link"/>
        <child link="rh_rotate_top_link"/>
        <origin xyz="0.0 0.0 0.0" rpy="0.0 0.0 0.0"/>
    </joint>

    <joint name="joint_8" type="revolute">
        <parent link="rh_rotate_link"/>
        <child link="rh_gripper1_link"/>
        <axis xyz="1 0 0"/>
        <limit lower="${-PI/6}" upper="0" velocity="50.0" effort="1000.0"/>
        <origin xyz="-0.015 -0.02 -0.048" rpy="0 0 0"/>
    </joint>
    
    <joint name="joint_21" type="revolute">
        <mimic joint="joint_8" multiplier="-1"/>
        <parent link="rh_rotate_link"/>
        <child link="rh_gripper2_link"/>
        <axis xyz="1 0 0"/>
        <limit lower="0" upper="${PI/6}" velocity="50.0" effort="1000.0"/>
        <origin xyz="-0.015 0.02 -0.048" rpy="0 0 0"/>
    </joint>

    <joint name="pad_rh_r" type="fixed">
        <parent link="rh_gripper1_link"/>
        <child link="rh_gripper1_pad_link"/>
        <origin xyz="0 0.015 -0.041" rpy="0.0 0.0 0.0"/>
    </joint>

    <joint name="pad_rh_l" type="fixed">
        <parent link="rh_gripper2_link"/>
        <child link="rh_gripper2_pad_link"/>
        <origin xyz="0 -0.015 -0.041" rpy="0.0 0.0 0.0"/>
    </joint> 
    

    <!-- Left Arm Joints-->
    <joint name="joint_9" type="revolute">
        <parent link="chest_link"/>
        <child link="shoulder_lh_link"/>
        <axis xyz="0 1 0"/>
        <limit lower="${-PI/2}" upper="${PI/2}" velocity="50.0" effort="1000.0"/>
        <origin xyz="0.0 0.085 0.05" rpy="0 0 0"/>
    </joint>

    <joint name="joint_10" type="revolute">
        <parent link="shoulder_lh_link"/>
        <child link="sh_lh_lift_link"/>
        <axis xyz="1 0 0"/>
        <limit lower="0" upper="${PI/2}" velocity="50.0" effort="1000.0"/>
        <origin xyz="-0.008 0.027 0" rpy="0 0 0"/>
    </joint>

    <joint name="joint_11" type="revolute">
        <parent link="sh_lh_lift_link"/>
        <child link="sh_lh_rotate_link"/>
        <axis xyz="0 0 1"/>
        <limit lower="${-PI/2}" upper="${PI/2}" velocity="50.0" effort="1000.0"/>
        <origin xyz="0 0 -0.04" rpy="0 0 0"/>
    </joint>

    <joint name="joint_12" type="revolute">
        <parent link="sh_lh_rotate_link"/>
        <child link="elbow_lh_link"/>
        <axis xyz="0 1 0"/>
        <limit lower="${-PI/2}" upper="0" velocity="50.0" effort="1000.0"/>
        <origin xyz="0 0 -0.13" rpy="0 0 0"/>
    </joint>

    <joint name="joint_13" type="revolute">
        <parent link="elbow_lh_link"/>
        <child link="lh_rotate_link"/>
        <axis xyz="0 0 1"/>
        <limit lower="${-PI/2}" upper="0" velocity="50.0" effort="1000.0"/>
        <origin xyz="0 0.015 -0.13" rpy="0 0 0"/>
    </joint>
    
    <!-- Left Gripper Joints-->
    
    <joint name="gripper_body_lh" type="fixed">
        <parent link="lh_rotate_link"/>
        <child link="lh_rotate_top_link"/>
        <origin xyz="0.0 0.0 0.0" rpy="0.0 0.0 0.0"/>
    </joint>

    <joint name="joint_14" type="revolute">
        <parent link="lh_rotate_link"/>
        <child link="lh_gripper1_link"/>
        <axis xyz="1 0 0"/>
        <limit lower="${-PI/6}" upper="0" velocity="50.0" effort="1000.0"/>
        <origin xyz="-0.015 -0.02 -0.048" rpy="0 0 0"/>
    </joint>
    
    <joint name="joint_22" type="revolute">
        <mimic joint="joint_14" multiplier="-1"/>
        <parent link="lh_rotate_link"/>
        <child link="lh_gripper2_link"/>
        <axis xyz="1 0 0"/>
        <limit lower="0" upper="${PI/6}" velocity="50.0" effort="1000.0"/>
        <origin xyz="-0.015 0.02 -0.048" rpy="0 0 0"/>
    </joint>

    <joint name="pad_lh_r" type="fixed">
        <parent link="lh_gripper1_link"/>
        <child link="lh_gripper1_pad_link"/>
        <origin xyz="0 0.015 -0.041" rpy="0.0 0.0 0.0"/>
    </joint>

    <joint name="pad_lh_l" type="fixed">
        <parent link="lh_gripper2_link"/>
        <child link="lh_gripper2_pad_link"/>
        <origin xyz="0 -0.015 -0.041" rpy="0.0 0.0 0.0"/>
    </joint>


    <!-- Right Leg Joints-->

    <joint name="joint_15" type="revolute">
        <parent link="hip_link"/>
        <child link="hip_rh_link"/>
        <axis xyz="0 1 0"/>
        <limit lower="${-PI/2}" upper="${PI/2}" velocity="50.0" effort="1000.0"/>
        <origin xyz="-0.007 -0.042 -0.024" rpy="0 0 0"/>
    </joint>

    <joint name="joint_16" type="revolute">
        <parent link="hip_rh_link"/>
        <child link="knie_rh_link"/>
        <axis xyz="0 1 0"/>
        <limit lower="0" upper="${PI/2}" velocity="50.0" effort="1000.0"/>
        <origin xyz="0 0 -0.185" rpy="0 0 0"/>
    </joint>
    
    <joint name="joint_17" type="revolute">
        <parent link="knie_rh_link"/>
        <child link="foot_rh_link"/>
        <axis xyz="0 1 0"/>
        <limit lower="${-PI/4}" upper="${PI/4}" velocity="50.0" effort="1000.0"/>
        <origin xyz="0 0 -0.18" rpy="0 0 0"/>
    </joint>

    <!-- Left Leg Joints-->

    <joint name="joint_18" type="revolute">
        <parent link="hip_link"/>
        <child link="hip_lh_link"/>
        <axis xyz="0 1 0"/>
        <limit lower="${-PI/2}" upper="${PI/2}" velocity="50.0" effort="1000.0"/>
        <origin xyz="-0.007 0.042 -0.024" rpy="0 0 0"/>
    </joint>
    
    <joint name="joint_19" type="revolute">
        <parent link="hip_lh_link"/>
        <child link="knie_lh_link"/>
        <axis xyz="0 1 0"/>
        <limit lower="0" upper="${PI/2}" velocity="50.0" effort="1000.0"/>
        <origin xyz="0 0 -0.185" rpy="0 0 0"/>
    </joint>

    <joint name="joint_20" type="revolute">
        <parent link="knie_lh_link"/>
        <child link="foot_lh_link"/>
        <axis xyz="0 1 0"/>
        <limit lower="${-PI/4}" upper="${PI/4}" velocity="50.0" effort="1000.0"/>
        <origin xyz="0 0 -0.18" rpy="0 0 0"/>
    </joint>   

    <!-- Transmissions-->

    <xacro:default_transmission number="1"/>
    <xacro:default_transmission number="2"/>
    <xacro:default_transmission number="3"/>
    <xacro:default_transmission number="4"/>
    <xacro:default_transmission number="5"/>
    <xacro:default_transmission number="6"/>
    <xacro:default_transmission number="7"/>
    <xacro:default_transmission number="8"/>
    <xacro:default_transmission number="9"/>
    <xacro:default_transmission number="10"/>
    <xacro:default_transmission number="11"/>
    <xacro:default_transmission number="12"/>
    <xacro:default_transmission number="13"/>
    <xacro:default_transmission number="14"/>
    <xacro:default_transmission number="15"/>
    <xacro:default_transmission number="16"/>
    <xacro:default_transmission number="17"/>
    <xacro:default_transmission number="18"/>
    <xacro:default_transmission number="19"/>
    <xacro:default_transmission number="20"/>

    
</robot>